Workbook
Name dews212: #REF!
Name dews212: #REF!
Name dews212: #REF!
Name dews212: #REF!
Name dews212: #REF!
Name dews212: #REF!
Name dews212: #REF!
Name dews212: #REF!
Name dews212: #REF!
Name dews212: #REF!
Name dews212: #REF!
Name Excel_BuiltIn_Print_Area_23: #REF!
Name Excel_BuiltIn_Print_Area_23: #REF!
Name Excel_BuiltIn_Print_Area_23: #REF!
Name Excel_BuiltIn_Print_Area_23: #REF!
Name Excel_BuiltIn_Print_Area_23: #REF!
Name Excel_BuiltIn_Print_Area_23: #REF!
Name Excel_BuiltIn_Print_Area_23: #REF!
Name Excel_BuiltIn_Print_Area_23: #REF!
Name Excel_BuiltIn_Print_Area_23: #REF!
Name Excel_BuiltIn_Print_Area_23: #REF!
Name Excel_BuiltIn_Print_Area_23: #REF!
Name Excel_BuiltIn_Print_Area_24: #REF!
Name Excel_BuiltIn_Print_Area_24: #REF!
Name Excel_BuiltIn_Print_Area_24: #REF!
Name Excel_BuiltIn_Print_Area_24: #REF!
Name Excel_BuiltIn_Print_Area_24: #REF!
Name Excel_BuiltIn_Print_Area_24: #REF!
Name Excel_BuiltIn_Print_Area_24: #REF!
Name Excel_BuiltIn_Print_Area_24: #REF!
Name Excel_BuiltIn_Print_Area_24: #REF!
Name Excel_BuiltIn_Print_Area_24: #REF!
Name Excel_BuiltIn_Print_Area_24: #REF!
Name Excel_BuiltIn_Print_Area_29: #REF!
Name Excel_BuiltIn_Print_Area_29: #REF!
Name Excel_BuiltIn_Print_Area_29: #REF!
Name Excel_BuiltIn_Print_Area_29: #REF!
Name Excel_BuiltIn_Print_Area_29: #REF!
Name Excel_BuiltIn_Print_Area_29: #REF!
Name Excel_BuiltIn_Print_Area_29: #REF!
Name Excel_BuiltIn_Print_Area_29: #REF!
Name Excel_BuiltIn_Print_Area_29: #REF!
Name Excel_BuiltIn_Print_Area_29: #REF!
Name Excel_BuiltIn_Print_Area_29: #REF!
Name qawdeds12321: #REF!
Name qawdeds12321: #REF!
Name qawdeds12321: #REF!
Name qawdeds12321: #REF!
Name qawdeds12321: #REF!
Name qawdeds12321: #REF!
Name qawdeds12321: #REF!
Name qawdeds12321: #REF!
Name qawdeds12321: #REF!
Name qawdeds12321: #REF!
Name qawdeds12321: #REF!
Name а: #REF!
Name а: #REF!
Name а: #REF!
Name а: #REF!
Name а: #REF!

Sheet ПОДПИСИ
B2: Реконструкция ВЛ 10 кВ ДТ-9 от опоры №20 до опоры №115 в части замены опор и провода (протяженностью 8 км), с установкой коммутационных аппаратов в количестве 1 шт. | C2: ООО «СЭТ»
A6: КТО | B6: Должность | C6: Фамилия Имя Отчество | D6: ФИО
A7: Генподрядчик | B7: Директор по строительству ООО «СЭТ» | C7: Потоцкий А.А. | D7: А.А. Потоцкий
A9: Производитель работ | B9: Начальник участка ООО «СЭТ» | C9: Нугуманов М.А. | D9: М.А. Нугуманов
A11: Тех надзор | B11: Ведущий инженер строительного контроля ООО «СЭТ» | C11: Кольцов А.Г. | D11: А.Г. Кольцов
A13: Представители иных лиц | B13: Ведущий инженер отдела строительного контроля АО "ЛЭСР" | C13: Сафуанова В.А. | D13: В.А. Сафуанова
A90: =CONCATENATE(ПОДПИСИ!B13," ",ПОДПИСИ!#REF!) -> #REF!

Sheet Лист1
A1: Кабель силовой с изоляцией сшитого полиэтилена, сеч. 150 | B1: АПвПу2г 1х150/70 | C1: м | D1: 5711.15
A2: Кабель силовой с изоляцией сшитого полиэтилена, сеч. 240 | B2: АПвБШп 4х240 | C2: м | D2: 402.96
A3: Муфта соединительная кабельная | B3: ПСТ(с)-О-10-150...240 | C3: компл | D3: 21
A4: Муфта концевая кабельная | B4: ПКВТ(Н)-О-10-150...240 | C4: шт | D4: 2
A5: Труба ПЭ ЭНЕРГОПЛАСТ ТС3 DN160 SN32 | B5: ТУ 22.21.21-002-16073610-2019 | C5: м | D5: 1360.3
A6: Труба ПЭ ЭНЕРГОПЛАСТ ТС2 DN160 SN16 | B6: ТУ 22.21.21-002-16073610-2019 | C6: м | D6: 158.46
A7: Плита пеноплекс 1200х600х100 | C7: шт | D7: 252
A8: Уплотнитель кабельных проходов | B8: УкПт-Р-175/50 | C8: шт | D8: 52
A9: Заглушка для ПЭ труб φ160 | C9: шт | D9: 18
A10: Плита закрытия кабеля | B10: ПЗК 240х480х16 | C10: шт | D10: 2706
A11: Песок строительный | C11: м3 | D11: 240.72
A12: Бентонит | B12: Super bore | C12: т | D12: 26.415
A13: Полимер | B13: Supra Xan | C13: т | D13: 2.6415
A14: Вода | C14: м3 | D14: 1320.82
A15: Кабельный киоск | B15: КЛ-211 | C15: шт | D15: 2
A16: Сталь угловая 63х63х6 | C16: м | D16: 28.48
A17: Сталь листовая толщиной 2мм 950х400 | C17: шт | D17: 4
A18: Сталь листовая толщиной 2мм 380х400 | C18: шт | D18: 4
A19: Сталь полосовая 40х4 | C19: м | D19: 12
A20: Бирка "Домик" маркировочная | B20: 150х100х2мм | C20: шт | D20: 12
A21: Кабельные стяжки | B21: 2,5х100 | C21: шт | D21: 12
A22: Щебень М1200, фр. 20-40 | C22: м3 | D22: 0.4
A23: Муфта концевая кабельная | B23: 4ПКВНТпН-Б-1-150...240 | C23: шт | D23: 6
A24: Кирпич полнотелый 250х120х65 | C24: шт | D24: 465
A25: Асфальтобетон крупнозернистый плотный тип А, марка I | C25: м3 | D25: 4.875
A26: Асфальтобетон мелкозернистый плотного тип А, марка I | C26: м3 | D26: 4.875
A27: Щебень М1200, фр. 40-70 | C27: м3 | D27: 24.57
A28: Битумная эмульсия | B28: ГОСТ Р 52128-2003 | C28: кг | D28: 28.67
A29: Грунт плодородный | C29: м3 | D29: 2819.5
A30: Семена газонных трав | C30: кг | D30: 125.85

Sheet Титул 
V2: Приложение И, СП 48.13330.2019
B9: ЖУРНАЛ
B10: ВХОДНОГО УЧЕТА И КОНТРОЛЯ КАЧЕСТВА ПОЛУЧАЕМЫХ ДЕТАЛЕЙ,
B11: МАТЕРИАЛОВ, ИЗДЕЛИЙ, КОНСТРУКЦИЙ И ОБОРУДОВАНИЯ
B16: Наименование объекта | G16: =ПОДПИСИ!B2 -> Реконструкция ВЛ 10 кВ ДТ-9 от опоры №20 до опоры №115 в части замены опор и провода (протяженностью 8 км), с установкой коммутационных аппаратов в количестве 1 шт.
B18: Адрес объекта
B20: Наименование строительной организации
G21: =ПОДПИСИ!C2 -> ООО «СЭТ»
T26: Начат | V26: 11 ноября | AA26: 20 | AB26: 24 | AC26: г.
T28: Окончен | V28: 12 ноября | AA28: 20 | AB28: 24 | AC28: г.
F58: IД-72/22

Sheet Жвх.к
A1: Дата поступл. | B1: Наименование продукции | C1: Количество (масса), партия, номер | D1: Изготовитель/ Поставщик | E1: Сертификат качества (паспорт, накладная) | F1: Вид контроля (визуальный, инструментальный, лабораторный) | G1: Заключение о соответствии, подпись лица, ответственного за входной контроль | H1: Подтверждение представителя строительного контроля Заказчика о выполнении в полном объеме процедуры входного контроля
A2: 1 | B2: 2 | C2: 3 | D2: 4 | E2: 5 | F2: 6 | G2: 7 | H2: 8
A3: 45607 | B3: Монтажный комплект для установки РЛК на опору СВ110 в комплекте с кронштейном разъединителя, кронштейном привода, комплектом тяг h-6500 мм КМЧ РЛК | C3: 1 компл. | D3: ООО «Тд «Электротехмонтаж» | E3: Накладная №811 | F3: Визуальный | G3: Соответствует Нугуматов М.А.
A4: 45607 | B4: Привод разъединителя РЛК.1б-10.IV/400УХЛ1 ПР-01-07 УХЛ1 | C4: 1 шт. | D4: ООО "КАСПИЙ-ЭЛЕКТРО" | E4: Сертификат соответствия РОСС RU.З2001.04ИБФ1.ОСП20.18595 с 20.04.2022 по 19.04.2025 | F4: Визуальный | G4: Соответствует Нугуматов М.А.
A5: 45607 | B5: Разъединитель линейный качающего типа, с полимерными изоляторами РЛК.1б-10.IV/630 УХЛ1 | C5: 1 шт. | D5: ООО "КАСПИЙ-ЭЛЕКТРО" | E5: Сертификат соответствия РОСС RU.З2001.04ИБФ1.ОСП20.18595 с 20.04.2022 по 19.04.2025 | F5: Визуальный | G5: Соответствует Нугуматов М.А. | J5: 1
A6: 45607 | B6: Разрядник мультикамерный РМК-20-IV-УХЛ1 | C6: 108 шт. | D6: АО "НПО "Стример" | E6: Сертификат соответствия №РОСС RU.ЕФ01.Н00004-22 с 10.04.2022 по 09.04.2025 | F6: Визуальный | G6: Соответствует Нугуматов М.А. | J6: 1
A7: 45607 | B7: Разрядник мультикамерный экранного типа РМКЭ-10-IV-УХЛ1 | C7: 30 шт. | D7: АО "НПО "Стример" | E7: Сертификат соответствия №РОСС RU.ЕФ01.Н00004-22 с 10.04.2022 по 09.04.2025 | F7: Визуальный | G7: Соответствует Нугуматов М.А. | J7: 1
A8: 45607 | B8: Устройство для наложения защитного заземления CE 3 | C8: 63 шт. | D8: ООО «Тд «Электротехмонтаж» | E8: Накладная №811 | F8: Визуальный | G8: Соответствует Нугуматов М.А.
A9: 45607 | B9: Провод линии СИП-3 1х120 | C9: 18387 м | D9: ООО "КЗ "ЦВЕТЛИТ" | E9: Паспорт качества №№24Т1-5845 от 21.07.2024 г.; Паспорт качества №№24Т1-5844 от 21.07.2024 г.; Паспорт качества №№24Т1-5847 от 21.07.2024 г; Паспорт качества №№24Т1-5851 от 21.07.2024 г. | F9: Визуальный | G9: Соответствует Нугуматов М.А. | J9: 1 | L9: =18324+63 -> 18387
A10: 45607 | B10: Стойка железобетонная СВ110-3,5 (у) | C10: 6 шт. | D10: ЗАО "Митеп-Волга" | E10: Сертификат соответствия №РОСС BY.HB61.H30298 от 09.11.2021 сроком действия до 08.11.2024 | F10: Визуальный | G10: Соответствует Нугуматов М.А. | J10: 1
A11: 45607 | B11: Заземляющий проводник ЗП1 | C11: 38,9 м | D11: ООО «Тд «Электротехмонтаж» | E11: Накладная №811 | F11: Визуальный | G11: Соответствует Нугуматов М.А.
A12: 45607 | B12: Траверса ТМ63 | C12: 2 шт. | D12: ООО "НИЛЕД" | E12: Сертификат соответствия №РОСС RU.НЕ06.Н05218 от 12.04.2023 сроком действия до 11.04.2026 | F12: Визуальный | G12: Соответствует Нугуматов М.А. | J12: 1
A13: 45607 | B13: Траверса ТМ65 | C13: 6 шт. | D13: ООО "НИЛЕД" | E13: Сертификат соответствия №РОСС RU.НЕ06.Н05218 от 12.04.2023 сроком действия до 11.04.2026 | F13: Визуальный | G13: Соответствует Нугуматов М.А. | J13: 1
A14: 45607 | B14: Траверса ТМ66 | C14: 5 шт. | D14: ООО "НИЛЕД" | E14: Сертификат соответствия №РОСС RU.НЕ06.Н05218 от 12.04.2023 сроком действия до 11.04.2026 | F14: Визуальный | G14: Соответствует Нугуматов М.А. | J14: 1
A15: 45607 | B15: Траверса ТМ67 | C15: 1 шт. | D15: ООО "НИЛЕД" | E15: Сертификат соответствия №РОСС RU.НЕ06.Н05218 от 12.04.2023 сроком действия до 11.04.2026 | F15: Визуальный | G15: Соответствует Нугуматов М.А. | J15: 1
A16: 45607 | B16: Траверса ТМ68 | C16: 1 шт. | D16: ООО "НИЛЕД" | E16: Сертификат соответствия №РОСС RU.НЕ06.Н05218 от 12.04.2023 сроком действия до 11.04.2026 | F16: Визуальный | G16: Соответствует Нугуматов М.А. | J16: 1
A17: 45607 | B17: Траверса ТМ73 | C17: 2 шт. | D17: ООО "НИЛЕД" | E17: Сертификат соответствия №РОСС RU.НЕ06.Н05218 от 12.04.2023 сроком действия до 11.04.2026 | F17: Визуальный | G17: Соответствует Нугуматов М.А. | J17: 1
A18: 45607 | B18: Траверса ТМ74 | C18: 2 шт. | D18: ООО "НИЛЕД" | E18: Сертификат соответствия №РОСС RU.НЕ06.Н05218 от 12.04.2023 сроком действия до 11.04.2026 | F18: Визуальный | G18: Соответствует Нугуматов М.А. | J18: 1
A19: 45607 | B19: Крепление подкоса У52 | C19: 5 шт. | D19: ООО «Тд «Электротехмонтаж» | E19: Накладная №811 | F19: Визуальный | G19: Соответствует Нугуматов М.А.
A20: 45607 | B20: Хомут Х51 | C20: 7 шт. | D20: ООО «Тд «Электротехмонтаж» | E20: Накладная №811 | F20: Визуальный | G20: Соответствует Нугуматов М.А.
A21: 45607 | B21: Зажим плашечный ПС-2-1 | C21: 184 шт. | D21: ООО «Тд «Электротехмонтаж» | E21: Накладная №811 | F21: Визуальный | G21: Соответствует Нугуматов М.А.
A22: 45607 | B22: Вязка спиральная СВ 120 | C22: 676 шт. | D22: ООО «Тд «Электротехмонтаж» | E22: Накладная №811 | F22: Визуальный | G22: Соответствует Нугуматов М.А.
A23: 45607 | B23: Метал. лента 20x0,7x1000 мм F 207 | C23: 1440 шт. | D23: ООО «Тд «Электротехмонтаж» | E23: Накладная №811 | F23: Визуальный | G23: Соответствует Нугуматов М.А.
A24: 45607 | B24: Изолятор штыревой ПШИ20 | C24: 33 шт. | D24: ООО «Тд «Электротехмонтаж» | E24: Накладная №811 | F24: Визуальный | G24: Соответствует Нугуматов М.А.
A25: 45607 | B25: Бугель для фиксации ленты NB 20 | C25: 960 шт. | D25: ООО «Тд «Электротехмонтаж» | E25: Накладная №811 | F25: Визуальный | G25: Соответствует Нугуматов М.А.
A26: 45607 | B26: Зажим анкерный PAZ 3 | C26: 168 шт. | D26: ООО «Тд «Электротехмонтаж» | E26: Накладная №811 | F26: Визуальный | G26: Соответствует Нугуматов М.А.
A27: 45607 | B27: Изолятор подвесной SML 70/20ГС | C27: 168 шт. | D27: ООО «Тд «Электротехмонтаж» | E27: Накладная №811 | F27: Визуальный | G27: Соответствует Нугуматов М.А.
A28: 45607 | B28: Зажим ответвительный RP 150 | C28: 99 шт. | D28: ООО «Тд «Электротехмонтаж» | E28: Накладная №811 | F28: Визуальный | G28: Соответствует Нугуматов М.А.
A29: 45607 | B29: Зажим аппаратный А2А-120 | C29: 42 шт. | D29: ООО «Тд «Электротехмонтаж» | E29: Накладная №811 | F29: Визуальный | G29: Соответствует Нугуматов М.А.
A30: 45607 | B30: Колпачок К9 | C30: 33 шт. | D30: ООО «Тд «Электротехмонтаж» | E30: Накладная №811 | F30: Визуальный | G30: Соответствует Нугуматов М.А.
... A90: 45432 | B90: Щебень гранитный марки 1200-600 фр.40-70мм | C90: 2,1 м3 | D90: АО "ЛСР.БАЗОВЫЕ МАТЕРИАЛЫ" | E90: Декларация о соответствии ЕАЭС №RU Д-RU.РА01.В.11071/21 от 03.06.2021 сроком действия до 02.06.2026 | F90: Визуальный | G90: Соответствует Шлёнский С.В.
A91: 45432 | B91: Песок природный для строительных: работ средний с крупностью зерен размером свыше 5 мм-до 5% по массе | C91: 242 м3 | D91: ООО "ДК "Горизонт" | E91: Паспорт №31/08/22 от 31.08.2022 | F91: Визуальный | G91: Соответствует Шлёнский С.В. | J91: =226.2+15.84 -> 242.04
A92: 45432 | B92: Бетон марки В15 F50 W4 | C92: 0,19м3 / 429 кг | D92: АО "Группа Компаний "Монолит" | E92: Документ о качестве бетонной смеси №000364646 | F92: Визуальный | G92: Соответствует Шлёнский С.В.
A93: 45432 | B93: Краска антикоррозиционная ОС-12-03 | C93: 6,6 кг | D93: Петрович | E93: Накладная №480365203 | F93: Визуальный | G93: Соответствует Шлёнский С.В.
A94: 45432 | B94: Уголок стальной 32х32х4мм | C94: 174,3 кг | D94: Петрович | E94: Накладная №480365203 | F94: Визуальный | G94: Соответствует Шлёнский С.В.
A95: 45432 | B95: Полоса стальная 4х30мм | C95: 22,0 кг | D95: Петрович | E95: Накладная №480365203 | F95: Визуальный | G95: Соответствует Шлёнский С.В.
A96: 45432 | B96: Стальной лист в=2мм | C96: 4,3 кг | D96: Петрович | E96: Накладная №480365203 | F96: Визуальный | G96: Соответствует Шлёнский С.В.
A97: 45432 | B97: Сетка №25х25 шириной 1960х1880 мм | C97: 56,4 кг | D97: Петрович | E97: Накладная №480365203 | F97: Визуальный | G97: Соответствует Шлёнский С.В.
A98: 45432 | B98: Проволока Ø4мм | C98: 10,3 кг | D98: Петрович | E98: Накладная №480365203 | F98: Визуальный | G98: Соответствует Шлёнский С.В.
A99: 45432 | B99: Труба водогазопроводная Ø 80 мм (L=2400мм) | C99: 14 шт / 199кг | D99: Петрович | E99: Накладная №480365203 | F99: Визуальный | G99: Соответствует Шлёнский С.В.
...

Sheet Жвх.к (т)
B7: =ПОДПИСИ!C2 -> ООО «СЭТ»
B8: (Наименование организации)
A13: ЖУРНАЛ
A14: УЧЕТА РЕЗУЛЬТАТОВ ВХОДНОГО КОНТРОЛЯ
A15: ПРОДУКЦИИ ДЛЯ СТРОИТЕЛЬСТВА, РЕКОНСТРУКЦИИ
C17: =ПОДПИСИ!B2 -> Реконструкция ВЛ 10 кВ ДТ-9 от опоры №20 до опоры №115 в части замены опор и провода (протяженностью 8 км), с установкой коммутационных аппаратов в количестве 1 шт.
C20: (Наименование объекта строительства, реконструкции)
C27: Начало работ | F27: "11" ноября 2024 | N27: Окончание работ | R27: "12" ноября 2024

Sheet Форма журнала
A1: Нумерация для АВК | B1: № п/п | C1: Дата доставки | D1: Наименование материалов, изделий, конструкций, оборудования | E1: Кол-во | F1: Поставщик | G1: Наименование и номер документа изготовителя | H1: Результат проверки сопроводительных документов производителя и визуального осмотра на соответствие требованиям утверждённой проектной документации и соответствующим документам по стандартизации | I1: Решение о необходимости проведения лабораторного контроля | J1: Результат лабораторного контроля | K1: Подпись лица, осуществляющего контроль | L1: 1 | M1: № ЗАК
B2: 1 | C2: 2 | D2: 3 | E2: 4 | F2: 5 | G2: 6 | H2: 7 | I2: 8 | J2: 9 | K2: 10 | L2: 11
A3: 1 | B3: =SUBTOTAL(9,$L$3:L3) -> 0 | C3: =IF(Жвх.к!$J3=1,Жвх.к!A3,"") | D3: =IF(Жвх.к!$J3=1,Жвх.к!B3,"") | E3: =IF(Жвх.к!$J3=1,Жвх.к!C3,"") | F3: =IF(Жвх.к!$J3=1,Жвх.к!D3,"") | G3: =IF(Жвх.к!$J3=1,Жвх.к!E3,"") | H3: Соответствуют | I3: - | J3: - | L3: =IF(C3="",0,1) -> 0 | M3: IЗ-81/22
A4: 2 | B4: =SUBTOTAL(9,$L$3:L4) -> 0 | C4: =IF(Жвх.к!$J4=1,Жвх.к!A4,"") | D4: =IF(Жвх.к!$J4=1,Жвх.к!B4,"") | E4: =IF(Жвх.к!$J4=1,Жвх.к!C4,"") | F4: =IF(Жвх.к!$J4=1,Жвх.к!D4,"") | G4: =IF(Жвх.к!$J4=1,Жвх.к!E4,"") | H4: Соответствуют | I4: - | J4: - | L4: =IF(C4="",0,1) -> 0 | M4: IЗ-104/22
A5: 3 | B5: =SUBTOTAL(9,$L$3:L5) -> 1 | C5: =IF(Жвх.к!$J5=1,Жвх.к!A5,"") -> 45607 | D5: =IF(Жвх.к!$J5=1,Жвх.к!B5,"") -> Разъединитель линейный качающего типа, с полимерными изоляторами РЛК.1б-10.IV/630 УХЛ1 | E5: =IF(Жвх.к!$J5=1,Жвх.к!C5,"") -> 1 шт. | F5: =IF(Жвх.к!$J5=1,Жвх.к!D5,"") -> ООО "КАСПИЙ-ЭЛЕКТРО" | G5: =IF(Жвх.к!$J5=1,Жвх.к!E5,"") -> Сертификат соответствия РОСС RU.З2001.04ИБФ1.ОСП20.18595 с 20.04.2022 по 19.04.2025 | H5: Соответствуют | I5: - | J5: - | L5: =IF(C5="",0,1) -> 1 | M5: Отсутствует
A6: 4 | B6: =SUBTOTAL(9,$L$3:L6) -> 2 | C6: =IF(Жвх.к!$J6=1,Жвх.к!A6,"") -> 45607 | D6: =IF(Жвх.к!$J6=1,Жвх.к!B6,"") -> Разрядник мультикамерный РМК-20-IV-УХЛ1 | E6: =IF(Жвх.к!$J6=1,Жвх.к!C6,"") -> 108 шт. | F6: =IF(Жвх.к!$J6=1,Жвх.к!D6,"") -> АО "НПО "Стример" | G6: =IF(Жвх.к!$J6=1,Жвх.к!E6,"") -> Сертификат соответствия №РОСС RU.ЕФ01.Н00004-22 с 10.04.2022 по 09.04.2025 | H6: Соответствуют | I6: - | J6: - | L6: =IF(C6="",0,1) -> 1 | M6: I3-224/15
A7: 5 | B7: =SUBTOTAL(9,$L$3:L7) -> 3 | C7: =IF(Жвх.к!$J7=1,Жвх.к!A7,"") -> 45607 | D7: =IF(Жвх.к!$J7=1,Жвх.к!B7,"") -> Разрядник мультикамерный экранного типа РМКЭ-10-IV-УХЛ1 | E7: =IF(Жвх.к!$J7=1,Жвх.к!C7,"") -> 30 шт. | F7: =IF(Жвх.к!$J7=1,Жвх.к!D7,"") -> АО "НПО "Стример" | G7: =IF(Жвх.к!$J7=1,Жвх.к!E7,"") -> Сертификат соответствия №РОСС RU.ЕФ01.Н00004-22 с 10.04.2022 по 09.04.2025 | H7: Соответствуют | I7: - | J7: - | L7: =IF(C7="",0,1) -> 1 | M7: I3-224/15
A8: 6 | B8: =SUBTOTAL(9,$L$3:L8) -> 3 | C8: =IF(Жвх.к!$J8=1,Жвх.к!A8,"") | D8: =IF(Жвх.к!$J8=1,Жвх.к!B8,"") | E8: =IF(Жвх.к!$J8=1,Жвх.к!C8,"") | F8: =IF(Жвх.к!$J8=1,Жвх.к!D8,"") | G8: =IF(Жвх.к!$J8=1,Жвх.к!E8,"") | H8: Соответствуют | I8: - | J8: - | L8: =IF(C8="",0,1) -> 0
A9: 7 | B9: =SUBTOTAL(9,$L$3:L9) -> 4 | C9: =IF(Жвх.к!$J9=1,Жвх.к!A9,"") -> 45607 | D9: =IF(Жвх.к!$J9=1,Жвх.к!B9,"") -> Провод линии СИП-3 1х120 | E9: =IF(Жвх.к!$J9=1,Жвх.к!C9,"") -> 18387 м | F9: =IF(Жвх.к!$J9=1,Жвх.к!D9,"") -> ООО "КЗ "ЦВЕТЛИТ" | G9: =IF(Жвх.к!$J9=1,Жвх.к!E9,"") -> Паспорт качества №№24Т1-5845 от 21.07.2024 г.; Паспорт качества №№24Т1-5844 от 21.07.2024 г.; Паспорт качества №№24Т1-5847 от 21.07.2024 г; Паспорт качества №№24Т1-5851 от 21.07.2024 г. | H9: Соответствуют | I9: - | J9: - | L9: =IF(C9="",0,1) -> 1 | M9: IЗ-206/20
A10: 8 | B10: =SUBTOTAL(9,$L$3:L10) -> 5 | C10: =IF(Жвх.к!$J10=1,Жвх.к!A10,"") -> 45607 | D10: =IF(Жвх.к!$J10=1,Жвх.к!B10,"") -> Стойка железобетонная СВ110-3,5 (у) | E10: =IF(Жвх.к!$J10=1,Жвх.к!C10,"") -> 6 шт. | F10: =IF(Жвх.к!$J10=1,Жвх.к!D10,"") -> ЗАО "Митеп-Волга" | G10: =IF(Жвх.к!$J10=1,Жвх.к!E10,"") -> Сертификат соответствия №РОСС BY.HB61.H30298 от 09.11.2021 сроком действия до 08.11.2024 | H10: Соответствуют | I10: - | J10: - | L10: =IF(C10="",0,1) -> 1 | M10: IЗ-159/20
A11: 9 | B11: =SUBTOTAL(9,$L$3:L11) -> 5 | C11: =IF(Жвх.к!$J11=1,Жвх.к!A11,"") | D11: =IF(Жвх.к!$J11=1,Жвх.к!B11,"") | E11: =IF(Жвх.к!$J11=1,Жвх.к!C11,"") | F11: =IF(Жвх.к!$J11=1,Жвх.к!D11,"") | G11: =IF(Жвх.к!$J11=1,Жвх.к!E11,"") | H11: Соответствуют | I11: - | J11: - | L11: =IF(C11="",0,1) -> 0
A12: 10 | B12: =SUBTOTAL(9,$L$3:L12) -> 6 | C12: =IF(Жвх.к!$J12=1,Жвх.к!A12,"") -> 45607 | D12: =IF(Жвх.к!$J12=1,Жвх.к!B12,"") -> Траверса ТМ63 | E12: =IF(Жвх.к!$J12=1,Жвх.к!C12,"") -> 2 шт. | F12: =IF(Жвх.к!$J12=1,Жвх.к!D12,"") -> ООО "НИЛЕД" | G12: =IF(Жвх.к!$J12=1,Жвх.к!E12,"") -> Сертификат соответствия №РОСС RU.НЕ06.Н05218 от 12.04.2023 сроком действия до 11.04.2026 | H12: Соответствуют | I12: - | J12: - | L12: =IF(C12="",0,1) -> 1 | M12: Отсутствует
A13: 11 | B13: =SUBTOTAL(9,$L$3:L13) -> 7 | C13: =IF(Жвх.к!$J13=1,Жвх.к!A13,"") -> 45607 | D13: =IF(Жвх.к!$J13=1,Жвх.к!B13,"") -> Траверса ТМ65 | E13: =IF(Жвх.к!$J13=1,Жвх.к!C13,"") -> 6 шт. | F13: =IF(Жвх.к!$J13=1,Жвх.к!D13,"") -> ООО "НИЛЕД" | G13: =IF(Жвх.к!$J13=1,Жвх.к!E13,"") -> Сертификат соответствия №РОСС RU.НЕ06.Н05218 от 12.04.2023 сроком действия до 11.04.2026 | H13: Соответствуют | I13: - | J13: - | L13: =IF(C13="",0,1) -> 1 | M13: Отсутствует
A14: 12 | B14: =SUBTOTAL(9,$L$3:L14) -> 8 | C14: =IF(Жвх.к!$J13=1,Жвх.к!A13,"") -> 45607 | D14: =IF(Жвх.к!$J14=1,Жвх.к!B14,"") -> Траверса ТМ66 | E14: =IF(Жвх.к!$J14=1,Жвх.к!C14,"") -> 5 шт. | F14: =IF(Жвх.к!$J14=1,Жвх.к!D14,"") -> ООО "НИЛЕД" | G14: =IF(Жвх.к!$J14=1,Жвх.к!E14,"") -> Сертификат соответствия №РОСС RU.НЕ06.Н05218 от 12.04.2023 сроком действия до 11.04.2026 | H14: Соответствуют | I14: - | J14: - | L14: =IF(C14="",0,1) -> 1 | M14: Отсутствует
A15: 13 | B15: =SUBTOTAL(9,$L$3:L15) -> 9 | C15: =IF(Жвх.к!$J14=1,Жвх.к!A14,"") -> 45607 | D15: =IF(Жвх.к!$J15=1,Жвх.к!B15,"") -> Траверса ТМ67 | E15: =IF(Жвх.к!$J15=1,Жвх.к!C15,"") -> 1 шт. | F15: =IF(Жвх.к!$J15=1,Жвх.к!D15,"") -> ООО "НИЛЕД" | G15: =IF(Жвх.к!$J15=1,Жвх.к!E15,"") -> Сертификат соответствия №РОСС RU.НЕ06.Н05218 от 12.04.2023 сроком действия до 11.04.2026 | H15: Соответствуют | I15: - | J15: - | L15: =IF(C15="",0,1) -> 1 | M15: Отсутствует
A16: 14 | B16: =SUBTOTAL(9,$L$3:L16) -> 10 | C16: =IF(Жвх.к!$J15=1,Жвх.к!A15,"") -> 45607 | D16: =IF(Жвх.к!$J16=1,Жвх.к!B16,"") -> Траверса ТМ68 | E16: =IF(Жвх.к!$J16=1,Жвх.к!C16,"") -> 1 шт. | F16: =IF(Жвх.к!$J16=1,Жвх.к!D16,"") -> ООО "НИЛЕД" | G16: =IF(Жвх.к!$J16=1,Жвх.к!E16,"") -> Сертификат соответствия №РОСС RU.НЕ06.Н05218 от 12.04.2023 сроком действия до 11.04.2026 | H16: Соответствуют | I16: - | J16: - | L16: =IF(C16="",0,1) -> 1 | M16: Отсутствует
A17: 15 | B17: =SUBTOTAL(9,$L$3:L17) -> 11 | C17: =IF(Жвх.к!$J16=1,Жвх.к!A16,"") -> 45607 | D17: =IF(Жвх.к!$J17=1,Жвх.к!B17,"") -> Траверса ТМ73 | E17: =IF(Жвх.к!$J17=1,Жвх.к!C17,"") -> 2 шт. | F17: =IF(Жвх.к!$J17=1,Жвх.к!D17,"") -> ООО "НИЛЕД" | G17: =IF(Жвх.к!$J17=1,Жвх.к!E17,"") -> Сертификат соответствия №РОСС RU.НЕ06.Н05218 от 12.04.2023 сроком действия до 11.04.2026 | H17: Соответствуют | I17: - | J17: - | L17: =IF(C17="",0,1) -> 1 | M17: Отсутствует
A18: 16 | B18: =SUBTOTAL(9,$L$3:L18) -> 12 | C18: =IF(Жвх.к!$J17=1,Жвх.к!A17,"") -> 45607 | D18: =IF(Жвх.к!$J18=1,Жвх.к!B18,"") -> Траверса ТМ74 | E18: =IF(Жвх.к!$J18=1,Жвх.к!C18,"") -> 2 шт. | F18: =IF(Жвх.к!$J18=1,Жвх.к!D18,"") -> ООО "НИЛЕД" | G18: =IF(Жвх.к!$J18=1,Жвх.к!E18,"") -> Сертификат соответствия №РОСС RU.НЕ06.Н05218 от 12.04.2023 сроком действия до 11.04.2026 | H18: Соответствуют | I18: - | J18: - | L18: =IF(C18="",0,1) -> 1 | M18: Отсутствует
A19: 17 | B19: =SUBTOTAL(9,$L$3:L19) -> 13 | C19: =IF(Жвх.к!$J18=1,Жвх.к!A18,"") -> 45607 | D19: =IF(Жвх.к!$J19=1,Жвх.к!B19,"") | E19: =IF(Жвх.к!$J19=1,Жвх.к!C19,"") | F19: =IF(Жвх.к!$J19=1,Жвх.к!D19,"") | G19: =IF(Жвх.к!$J19=1,Жвх.к!E19,"") | H19: Соответствуют | I19: - | J19: - | L19: =IF(C19="",0,1) -> 1
A20: 18 | B20: =SUBTOTAL(9,$L$3:L20) -> 13 | C20: =IF(Жвх.к!$J19=1,Жвх.к!A19,"") | D20: =IF(Жвх.к!$J20=1,Жвх.к!B20,"") | E20: =IF(Жвх.к!$J20=1,Жвх.к!C20,"") | F20: =IF(Жвх.к!$J20=1,Жвх.к!D20,"") | G20: =IF(Жвх.к!$J20=1,Жвх.к!E20,"") | H20: Соответствуют | I20: - | J20: - | L20: =IF(C20="",0,1) -> 0 | M20: IЗ-200/22
A21: 19 | B21: =SUBTOTAL(9,$L$3:L21) -> 13 | C21: =IF(Жвх.к!$J20=1,Жвх.к!A20,"") | D21: =IF(Жвх.к!$J21=1,Жвх.к!B21,"") | E21: =IF(Жвх.к!$J21=1,Жвх.к!C21,"") | F21: =IF(Жвх.к!$J21=1,Жвх.к!D21,"") | G21: =IF(Жвх.к!$J21=1,Жвх.к!E21,"") | H21: Соответствуют | I21: - | J21: - | L21: =IF(C21="",0,1) -> 0 | M21: =VLOOKUP(F21,#REF!,#REF!) -> #REF!
A22: 20 | B22: =SUBTOTAL(9,$L$3:L22) -> 13 | C22: =IF(Жвх.к!$J21=1,Жвх.к!A21,"") | D22: =IF(Жвх.к!$J22=1,Жвх.к!B22,"") | E22: =IF(Жвх.к!$J22=1,Жвх.к!C22,"") | F22: =IF(Жвх.к!$J22=1,Жвх.к!D22,"") | G22: =IF(Жвх.к!$J22=1,Жвх.к!E22,"") | H22: Соответствуют | I22: - | J22: - | L22: =IF(C22="",0,1) -> 0 | M22: =VLOOKUP(F22,#REF!,#REF!) -> #REF!
A23: 21 | B23: =SUBTOTAL(9,$L$3:L23) -> 13 | C23: =IF(Жвх.к!$J22=1,Жвх.к!A22,"") | D23: =IF(Жвх.к!$J23=1,Жвх.к!B23,"") | E23: =IF(Жвх.к!$J23=1,Жвх.к!C23,"") | F23: =IF(Жвх.к!$J23=1,Жвх.к!D23,"") | G23: =IF(Жвх.к!$J23=1,Жвх.к!E23,"") | H23: Соответствуют | I23: - | J23: - | L23: =IF(C23="",0,1) -> 0 | M23: =VLOOKUP(F23,#REF!,#REF!) -> #REF!
A24: 22 | B24: =SUBTOTAL(9,$L$3:L24) -> 13 | C24: =IF(Жвх.к!$J23=1,Жвх.к!A23,"") | D24: =IF(Жвх.к!$J24=1,Жвх.к!B24,"") | E24: =IF(Жвх.к!$J24=1,Жвх.к!C24,"") | F24: =IF(Жвх.к!$J24=1,Жвх.к!D24,"") | G24: =IF(Жвх.к!$J24=1,Жвх.к!E24,"") | H24: Соответствуют | I24: - | J24: - | L24: =IF(C24="",0,1) -> 0 | M24: =VLOOKUP(F24,#REF!,#REF!) -> #REF!
A25: 23 | B25: =SUBTOTAL(9,$L$3:L25) -> 13 | C25: =IF(Жвх.к!$J24=1,Жвх.к!A24,"") | D25: =IF(Жвх.к!$J25=1,Жвх.к!B25,"") | E25: =IF(Жвх.к!$J25=1,Жвх.к!C25,"") | F25: =IF(Жвх.к!$J25=1,Жвх.к!D25,"") | G25: =IF(Жвх.к!$J25=1,Жвх.к!E25,"") | H25: Соответствуют | I25: - | J25: - | L25: =IF(C25="",0,1) -> 0 | M25: =VLOOKUP(F25,#REF!,#REF!) -> #REF!
A26: 24 | B26: =SUBTOTAL(9,$L$3:L26) -> 13 | C26: =IF(Жвх.к!$J25=1,Жвх.к!A25,"") | D26: =IF(Жвх.к!$J26=1,Жвх.к!B26,"") | E26: =IF(Жвх.к!$J26=1,Жвх.к!C26,"") | F26: =IF(Жвх.к!$J26=1,Жвх.к!D26,"") | G26: =IF(Жвх.к!$J26=1,Жвх.к!E26,"") | H26: Соответствуют | I26: - | J26: - | L26: =IF(C26="",0,1) -> 0 | M26: =VLOOKUP(F26,#REF!,#REF!) -> #REF!
A27: 25 | B27: =SUBTOTAL(9,$L$3:L27) -> 13 | C27: =IF(Жвх.к!$J26=1,Жвх.к!A26,"") | D27: =IF(Жвх.к!$J27=1,Жвх.к!B27,"") | E27: =IF(Жвх.к!$J27=1,Жвх.к!C27,"") | F27: =IF(Жвх.к!$J27=1,Жвх.к!D27,"") | G27: =IF(Жвх.к!$J27=1,Жвх.к!E27,"") | H27: Соответствуют | I27: - | J27: - | L27: =IF(C27="",0,1) -> 0 | M27: =VLOOKUP(F27,#REF!,#REF!) -> #REF!
A28: 26 | B28: =SUBTOTAL(9,$L$3:L28) -> 13 | C28: =IF(Жвх.к!$J27=1,Жвх.к!A27,"") | D28: =IF(Жвх.к!$J28=1,Жвх.к!B28,"") | E28: =IF(Жвх.к!$J28=1,Жвх.к!C28,"") | F28: =IF(Жвх.к!$J28=1,Жвх.к!D28,"") | G28: =IF(Жвх.к!$J28=1,Жвх.к!E28,"") | H28: Соответствуют | I28: - | J28: - | L28: =IF(C28="",0,1) -> 0 | M28: =VLOOKUP(F28,#REF!,#REF!) -> #REF!
A29: 27 | B29: =SUBTOTAL(9,$L$3:L29) -> 13 | C29: =IF(Жвх.к!$J28=1,Жвх.к!A28,"") | D29: =IF(Жвх.к!$J29=1,Жвх.к!B29,"") | E29: =IF(Жвх.к!$J29=1,Жвх.к!C29,"") | F29: =IF(Жвх.к!$J29=1,Жвх.к!D29,"") | G29: =IF(Жвх.к!$J29=1,Жвх.к!E29,"") | H29: Соответствуют | I29: - | J29: - | L29: =IF(C29="",0,1) -> 0 | M29: =VLOOKUP(F29,#REF!,#REF!) -> #REF!
A30: 28 | B30: =SUBTOTAL(9,$L$3:L30) -> 13 | C30: =IF(Жвх.к!$J29=1,Жвх.к!A29,"") | D30: =IF(Жвх.к!$J30=1,Жвх.к!B30,"") | E30: =IF(Жвх.к!$J30=1,Жвх.к!C30,"") | F30: =IF(Жвх.к!$J30=1,Жвх.к!D30,"") | G30: =IF(Жвх.к!$J30=1,Жвх.к!E30,"") | H30: Соответствуют | I30: - | J30: - | L30: =IF(C30="",0,1) -> 0 | M30: =VLOOKUP(F30,#REF!,#REF!) -> #REF!
A31: 29 | B31: =SUBTOTAL(9,$L$3:L31) -> 13 | C31: =IF(Жвх.к!$J30=1,Жвх.к!A30,"") | D31: =IF(Жвх.к!$J31=1,Жвх.к!B31,"") | E31: =IF(Жвх.к!$J31=1,Жвх.к!C31,"") | F31: =IF(Жвх.к!$J31=1,Жвх.к!D31,"") | G31: =IF(Жвх.к!$J31=1,Жвх.к!E31,"") | H31: Соответствуют | I31: - | J31: - | L31: =IF(C31="",0,1) -> 0 | M31: =VLOOKUP(F31,#REF!,#REF!) -> #REF!
A32: 30 | B32: =SUBTOTAL(9,$L$3:L32) -> 13 | C32: =IF(Жвх.к!$J31=1,Жвх.к!A31,"") | D32: =IF(Жвх.к!$J32=1,Жвх.к!B32,"") | E32: =IF(Жвх.к!$J32=1,Жвх.к!C32,"") | F32: =IF(Жвх.к!$J32=1,Жвх.к!D32,"") | G32: =IF(Жвх.к!$J32=1,Жвх.к!E32,"") | H32: Соответствуют | I32: - | J32: - | L32: =IF(C32="",0,1) -> 0 | M32: =VLOOKUP(F32,#REF!,#REF!) -> #REF!
A33: 31 | B33: =SUBTOTAL(9,$L$3:L33) -> 13 | C33: =IF(Жвх.к!$J32=1,Жвх.к!A32,"") | D33: =IF(Жвх.к!$J33=1,Жвх.к!B33,"") | E33: =IF(Жвх.к!$J33=1,Жвх.к!C33,"") | F33: =IF(Жвх.к!$J33=1,Жвх.к!D33,"") | G33: =IF(Жвх.к!$J33=1,Жвх.к!E33,"") | H33: Соответствуют | I33: - | J33: - | L33: =IF(C33="",0,1) -> 0 | M33: =VLOOKUP(F33,#REF!,#REF!) -> #REF!
A34: 32 | B34: =SUBTOTAL(9,$L$3:L34) -> 13 | C34: =IF(Жвх.к!$J33=1,Жвх.к!A33,"") | D34: =IF(Жвх.к!$J34=1,Жвх.к!B34,"") | E34: =IF(Жвх.к!$J34=1,Жвх.к!C34,"") | F34: =IF(Жвх.к!$J34=1,Жвх.к!D34,"") | G34: =IF(Жвх.к!$J34=1,Жвх.к!E34,"") | H34: Соответствуют | I34: - | J34: - | L34: =IF(C34="",0,1) -> 0
A35: 33 | B35: =SUBTOTAL(9,$L$3:L35) -> 13 | C35: =IF(Жвх.к!$J34=1,Жвх.к!A34,"") | D35: =IF(Жвх.к!$J35=1,Жвх.к!B35,"") | E35: =IF(Жвх.к!$J35=1,Жвх.к!C35,"") | F35: =IF(Жвх.к!$J35=1,Жвх.к!D35,"") | G35: =IF(Жвх.к!$J35=1,Жвх.к!E35,"") | H35: Соответствуют | I35: - | J35: - | L35: =IF(C35="",0,1) -> 0 | M35: =VLOOKUP(F35,#REF!,#REF!) -> #REF!
A36: 34 | B36: =SUBTOTAL(9,$L$3:L36) -> 13 | C36: =IF(Жвх.к!$J35=1,Жвх.к!A35,"") | D36: =IF(Жвх.к!$J36=1,Жвх.к!B36,"") | E36: =IF(Жвх.к!$J36=1,Жвх.к!C36,"") | F36: =IF(Жвх.к!$J36=1,Жвх.к!D36,"") | G36: =IF(Жвх.к!$J36=1,Жвх.к!E36,"") | H36: Соответствуют | I36: - | J36: - | L36: =IF(C36="",0,1) -> 0 | M36: =VLOOKUP(F36,#REF!,#REF!) -> #REF!
A37: 35 | B37: =SUBTOTAL(9,$L$3:L37) -> 13 | C37: =IF(Жвх.к!$J36=1,Жвх.к!A36,"") | D37: =IF(Жвх.к!$J37=1,Жвх.к!B37,"") | E37: =IF(Жвх.к!$J37=1,Жвх.к!C37,"") | F37: =IF(Жвх.к!$J37=1,Жвх.к!D37,"") | G37: =IF(Жвх.к!$J37=1,Жвх.к!E37,"") | H37: Соответствуют | I37: - | J37: - | L37: =IF(C37="",0,1) -> 0 | M37: IП-50/24
A38: 36 | B38: =SUBTOTAL(9,$L$3:L38) -> 13 | C38: =IF(Жвх.к!$J37=1,Жвх.к!A37,"") | D38: =IF(Жвх.к!$J38=1,Жвх.к!B38,"") | E38: =IF(Жвх.к!$J38=1,Жвх.к!C38,"") | F38: =IF(Жвх.к!$J38=1,Жвх.к!D38,"") | G38: =IF(Жвх.к!$J38=1,Жвх.к!E38,"") | H38: Соответствуют | I38: - | J38: - | L38: =IF(C38="",0,1) -> 0
A39: 37 | B39: =SUBTOTAL(9,$L$3:L39) -> 13 | C39: =IF(Жвх.к!$J38=1,Жвх.к!A38,"") | D39: =IF(Жвх.к!$J39=1,Жвх.к!B39,"") | E39: =IF(Жвх.к!$J39=1,Жвх.к!C39,"") | F39: =IF(Жвх.к!$J39=1,Жвх.к!D39,"") | G39: =IF(Жвх.к!$J39=1,Жвх.к!E39,"") | H39: Соответствуют | I39: - | J39: - | L39: =IF(C39="",0,1) -> 0 | M39: =VLOOKUP(F39,#REF!,#REF!) -> #REF!
A40: 38 | B40: =SUBTOTAL(9,$L$3:L40) -> 13 | C40: =IF(Жвх.к!$J39=1,Жвх.к!A39,"") | D40: =IF(Жвх.к!$J40=1,Жвх.к!B40,"") | E40: =IF(Жвх.к!$J40=1,Жвх.к!C40,"") | F40: =IF(Жвх.к!$J40=1,Жвх.к!D40,"") | G40: =IF(Жвх.к!$J40=1,Жвх.к!E40,"") | H40: Соответствуют | I40: - | J40: - | L40: =IF(C40="",0,1) -> 0 | M40: =VLOOKUP(F40,#REF!,#REF!) -> #REF!
...

Sheet АВК 3
H1: Приложение 2
H2: к Положению
A4: ФОРМА | K4: =MID(CELL("имяфайла",A1),SEARCH("]",CELL("имяфайла",A1))+1,LEN(CELL("имяфайла",A1))) -> АВК 3
F5: соответствует | K5: =RIGHT(K4,LEN(K4)-4)+2 -> 5
F7: (результат контроля продукции)
A8: Объект строительства: | D8: ='Жвх.к (т)'!C17 -> Реконструкция ВЛ 10 кВ ДТ-9 от опоры №20 до опоры №115 в части замены опор и провода (протяженностью 8 км), с установкой коммутационных аппаратов в количестве 1 шт.
A9: Заказчик строительства: | D9: ПАО "Россети Ленэнерго"
A11: =CONCATENATE("АКТ № ",INDIRECT("'Форма журнала'!R"&K5&"C2",0)) -> АКТ № 1
A12: ВХОДНОГО КОНТРОЛЯ
G13: =INDIRECT("'Форма журнала'!R"&K5&"C3",0) -> 45607
A14: (место проведения)
A15: Нами, комиссией | C15: ='Жвх.к (т)'!B7 -> ООО «СЭТ» | F15: по Приказу №23/10/24-8 от 23.10.2024г. в составе:
C16: (организация, от которой сформирована комиссия)
A17: Председателя
A18: =CONCATENATE(ПОДПИСИ!B7," ",ПОДПИСИ!C7) -> Директор по строительству ООО «СЭТ» Потоцкий А.А.
A19: и членов комиссии:
B20: =CONCATENATE(ПОДПИСИ!B9," ",ПОДПИСИ!C9) -> Начальник участка ООО «СЭТ» Нугуманов М.А.
B21: (должность, организация, фамилия, имя, отчество)
B22: =CONCATENATE(ПОДПИСИ!B11," ",ПОДПИСИ!C11) -> Ведущий инженер строительного контроля ООО «СЭТ» Кольцов А.Г.
B23: (должность, организация, фамилия, имя, отчество)
B25: (должность, организация, фамилия, имя, отчество)
A26: руководствуясь
A27: Приказом ПАО «Россети Ленэнерго» от 20.01.2020 г. №16 «Положение по организации и осуществлению входного контроля продукции для строительства и реконструкции объектов электросетевого комплекса ПAO «Ленэнерго»
A28: (документ, устанавливающий требования по организации и проведению входного контроля продукции)
A29: составлен настоящий акт о выполненном входном контроле продукции для строительства.
A30: 1. К входному контролю представлена следующая продукция:
A31: =INDIRECT("'Форма журнала'!R"&K5&"C4",0) -> Разъединитель линейный качающего типа, с полимерными изоляторами РЛК.1б-10.IV/630 УХЛ1
A32: (наименование продукции)
A33: 1.1 Наименование, номер документа, удостоверяющего качества и НТД на продукцию:
A34: =INDIRECT("'Форма журнала'!R"&K5&"C7",0) -> Сертификат соответствия РОСС RU.З2001.04ИБФ1.ОСП20.18595 с 20.04.2022 по 19.04.2025 | F34: НТД
A35: (Изготовитель, № документа и дата, № партии, Дата изготовления) | G35: (ГОСТ, ТУ, чертеж КМД)
A36: . | C36: =INDIRECT("'Форма журнала'!R"&K5&"C5",0) -> 1 шт. | F36: Кол-во в партии
C37: (штуки, объем, вес в ед. изм.) | G37: (штуки, объем, вес в ед. изм)
A38: 1.3 Поставщик: | C38: =INDIRECT("'Форма журнала'!R"&K5&"C6",0) -> ООО "КАСПИЙ-ЭЛЕКТРО" | F38: Договор
C39: (наименование организации) | G39: (Реквизиты договора на поставку)
A40: 2. Подготовка продукции к контролю по НТД: | F40: выполнена
F41: (выполнена/не выполнена)
A42: 3. При входном контроле проведены следующие контрольные мероприятия:
A43: Количество, масс, объем проверенной продукции (в ед. изм.) | E43: Вид контроля (НТД) и дата сдачи образцов (проб) на контроль | F43: Приборы контроля | G43: № прибора и дата проверки прибора | H43: № и дата протокола контроля | I43: Заключение по контролю (годен/не годен)
A44: Визуальным осмотром | C44: Инструментальными и приборными методами
...

Sheet Титул (СМР и Рек.)
V1: Приложение 3 к Положению
A5: ООО "Ясень-Электро"
A6: (Наименование организации)
B9: ЖУРНАЛ
B10: УЧЕТА РЕЗУЛЬТАТОВ ВХОДНОГО КОНТРОЛЯ
B11: ПРОДУКЦИИ ДЛЯ СТРОИТЕЛЬСТВА, РЕКОНСТРУКЦИИ
A13: Строительство двухтрансформаторной КТПН-6/0,4кВ с установкой двух трансформаторов мощностью не менее 0,160 МВА каждый, 2КЛ-6кВ длиной 2х0,4км, в том числе методом ГНБ длиной 2х0,25км, 2КЛ-0,4кВ длиной 2х0,02км, 2ВЛ-0,4км длиной 2х0,03км для технологического присоединения энергопринимающих устройств заявителя ИП Соболев В.В. по адресу: Ленинградская область, Ломоносовский район, МО «Низинское сельское поселение», деревня «Троицкая Гора», квартал 8, уч. 3 (22-036576)
A15: (Наименование объекта строительства, реконструкции)
T27: Начат | AA27: 20 | AC27: г.
T29: Окончен | AA29: 20 | AC29: г.

Sheet Лист регистрации АВК по спец.
J1: Лист 1
A2: Лист регистрации актов входного контроля продукции для строительства получаемой или приобретаемой по спецификации, представленной в составе рабочей документации
A3: № п/п | B3: Дата акта входного контроля | C3: № акта входного контроля | D3: Наименование продукции (тип, марка, обозначение НТД) | E3: Поставщик продукции | F3: Предприятие - изготовитель продукции | G3: № партии, заводской номер | H3: Количество, масса, объем проверенной продукции (в ед. изм.) | I3: Заключение о соответствии продукции требованиям НТД | J3: Подтверждение представителя строительного контроля Заказчика о выполнении в полном объеме процедуры входного контроля
A4: 1 | B4: 2 | C4: 3 | D4: 4 | E4: 5 | F4: 6 | G4: 7 | H4: 8 | I4: 9 | J4: 10

Sheet Лист регистрации АВК вне спец.
M1: Лист 2
A2: Лист учета результатов входного контроля приобретаемой продукции для строительства не учтенной в спецификациях рабочей документации
A3: Дата поступления | B3: Наименование продукции (тип, марка, обозначение НТД) | C3: Поставщик продукции | D3: Реквизиты документа о качестве продукции (Изготовитель, выдавший документ, номер и дата выдачи) | E3: № партии, заводской номер | F3: Количество, масса, объем продукции в партии (в ед. изм.) | G3: Количество, масса, объем поступившей продукции (в ед. изм.) | H3: Количество, масса, объем проверенной продукции (в ед. изм.) | I3: Дата передачи образцов (проб) на испытания | J3: Номер и дата протокола испытаний образцов (проб) | K3: Заключение о соответствии продукции требованиям НТД | L3: Подпись ответственного лица выполнившего входной контроль продукции | M3: Подтверждение представителя строительного контроля Заказчика о выполнении в полном объеме процедуры входного контроля
A4: 1 | B4: 2 | C4: 3 | D4: 4 | E4: 5 | F4: 6 | G4: 7 | H4: 8 | I4: 9 | J4: 10 | K4: 11 | L4: 12 | M4: 13

Sheet АВК 4
H1: Приложение 2
H2: к Положению
A4: ФОРМА | K4: =MID(CELL("имяфайла",A1),SEARCH("]",CELL("имяфайла",A1))+1,LEN(CELL("имяфайла",A1))) -> АВК 4
F5: соответствует | K5: =RIGHT(K4,LEN(K4)-4)+2 -> 6
F7: (результат контроля продукции)
A8: Объект строительства: | D8: ='Жвх.к (т)'!C17 -> Реконструкция ВЛ 10 кВ ДТ-9 от опоры №20 до опоры №115 в части замены опор и провода (протяженностью 8 км), с установкой коммутационных аппаратов в количестве 1 шт.
A9: Заказчик строительства: | D9: ПАО "Россети Ленэнерго"
A11: =CONCATENATE("АКТ № ",INDIRECT("'Форма журнала'!R"&K5&"C2",0)) -> АКТ № 2
A12: ВХОДНОГО КОНТРОЛЯ
G13: =INDIRECT("'Форма журнала'!R"&K5&"C3",0) -> 45607
A14: (место проведения)
A15: Нами, комиссией | C15: ='Жвх.к (т)'!B7 -> ООО «СЭТ» | F15: по Приказу №23/10/24-8 от 23.10.2024г. в составе:
C16: (организация, от которой сформирована комиссия)
A17: Председателя
A18: =CONCATENATE(ПОДПИСИ!B7," ",ПОДПИСИ!C7) -> Директор по строительству ООО «СЭТ» Потоцкий А.А.
A19: и членов комиссии:
B20: =CONCATENATE(ПОДПИСИ!B9," ",ПОДПИСИ!C9) -> Начальник участка ООО «СЭТ» Нугуманов М.А.
B21: (должность, организация, фамилия, имя, отчество)
B22: =CONCATENATE(ПОДПИСИ!B11," ",ПОДПИСИ!C11) -> Ведущий инженер строительного контроля ООО «СЭТ» Кольцов А.Г.
B23: (должность, организация, фамилия, имя, отчество)
B25: (должность, организация, фамилия, имя, отчество)
A26: руководствуясь
A27: Приказом ПАО «Россети Ленэнерго» от 20.01.2020 г. №16 «Положение по организации и осуществлению входного контроля продукции для строительства и реконструкции объектов электросетевого комплекса ПAO «Ленэнерго»
A28: (документ, устанавливающий требования по организации и проведению входного контроля продукции)
A29: составлен настоящий акт о выполненном входном контроле продукции для строительства.
A30: 1. К входному контролю представлена следующая продукция:
A31: =INDIRECT("'Форма журнала'!R"&K5&"C4",0) -> Разрядник мультикамерный РМК-20-IV-УХЛ1
A32: (наименование продукции)
A33: 1.1 Наименование, номер документа, удостоверяющего качества и НТД на продукцию:
A34: =INDIRECT("'Форма журнала'!R"&K5&"C7",0) -> Сертификат соответствия №РОСС RU.ЕФ01.Н00004-22 с 10.04.2022 по 09.04.2025 | F34: НТД
A35: (Изготовитель, № документа и дата, № партии, Дата изготовления) | G35: (ГОСТ, ТУ, чертеж КМД)
A36: . | C36: =INDIRECT("'Форма журнала'!R"&K5&"C5",0) -> 108 шт. | F36: Кол-во в партии
C37: (штуки, объем, вес в ед. изм.) | G37: (штуки, объем, вес в ед. изм)
A38: 1.3 Поставщик: | C38: =INDIRECT("'Форма журнала'!R"&K5&"C6",0) -> АО "НПО "Стример" | F38: Договор
C39: (наименование организации) | G39: (Реквизиты договора на поставку)
A40: 2. Подготовка продукции к контролю по НТД: | F40: выполнена
F41: (выполнена/не выполнена)
A42: 3. При входном контроле проведены следующие контрольные мероприятия:
A43: Количество, масс, объем проверенной продукции (в ед. изм.) | E43: Вид контроля (НТД) и дата сдачи образцов (проб) на контроль | F43: Приборы контроля | G43: № прибора и дата проверки прибора | H43: № и дата протокола контроля | I43: Заключение по контролю (годен/не годен)
A44: Визуальным осмотром | C44: Инструментальными и приборными методами
...

Sheet АВК 5
H1: Приложение 2
H2: к Положению
A4: ФОРМА | K4: =MID(CELL("имяфайла",A1),SEARCH("]",CELL("имяфайла",A1))+1,LEN(CELL("имяфайла",A1))) -> АВК 5
F5: соответствует | K5: =RIGHT(K4,LEN(K4)-4)+2 -> 7
F7: (результат контроля продукции)
A8: Объект строительства: | D8: ='Жвх.к (т)'!C17 -> Реконструкция ВЛ 10 кВ ДТ-9 от опоры №20 до опоры №115 в части замены опор и провода (протяженностью 8 км), с установкой коммутационных аппаратов в количестве 1 шт.
A9: Заказчик строительства: | D9: ПАО "Россети Ленэнерго"
A11: =CONCATENATE("АКТ № ",INDIRECT("'Форма журнала'!R"&K5&"C2",0)) -> АКТ № 3
A12: ВХОДНОГО КОНТРОЛЯ
G13: =INDIRECT("'Форма журнала'!R"&K5&"C3",0) -> 45607
A14: (место проведения)
A15: Нами, комиссией | C15: ='Жвх.к (т)'!B7 -> ООО «СЭТ» | F15: по Приказу №23/10/24-8 от 23.10.2024г. в составе:
C16: (организация, от которой сформирована комиссия)
A17: Председателя
A18: =CONCATENATE(ПОДПИСИ!B7," ",ПОДПИСИ!C7) -> Директор по строительству ООО «СЭТ» Потоцкий А.А.
A19: и членов комиссии:
B20: =CONCATENATE(ПОДПИСИ!B9," ",ПОДПИСИ!C9) -> Начальник участка ООО «СЭТ» Нугуманов М.А.
B21: (должность, организация, фамилия, имя, отчество)
B22: =CONCATENATE(ПОДПИСИ!B11," ",ПОДПИСИ!C11) -> Ведущий инженер строительного контроля ООО «СЭТ» Кольцов А.Г.
B23: (должность, организация, фамилия, имя, отчество)
B25: (должность, организация, фамилия, имя, отчество)
A26: руководствуясь
A27: Приказом ПАО «Россети Ленэнерго» от 20.01.2020 г. №16 «Положение по организации и осуществлению входного контроля продукции для строительства и реконструкции объектов электросетевого комплекса ПAO «Ленэнерго»
A28: (документ, устанавливающий требования по организации и проведению входного контроля продукции)
A29: составлен настоящий акт о выполненном входном контроле продукции для строительства.
A30: 1. К входному контролю представлена следующая продукция:
A31: =INDIRECT("'Форма журнала'!R"&K5&"C4",0) -> Разрядник мультикамерный экранного типа РМКЭ-10-IV-УХЛ1
A32: (наименование продукции)
A33: 1.1 Наименование, номер документа, удостоверяющего качества и НТД на продукцию:
A34: =INDIRECT("'Форма журнала'!R"&K5&"C7",0) -> Сертификат соответствия №РОСС RU.ЕФ01.Н00004-22 с 10.04.2022 по 09.04.2025 | F34: НТД
A35: (Изготовитель, № документа и дата, № партии, Дата изготовления) | G35: (ГОСТ, ТУ, чертеж КМД)
A36: . | C36: =INDIRECT("'Форма журнала'!R"&K5&"C5",0) -> 30 шт. | F36: Кол-во в партии
C37: (штуки, объем, вес в ед. изм.) | G37: (штуки, объем, вес в ед. изм)
A38: 1.3 Поставщик: | C38: =INDIRECT("'Форма журнала'!R"&K5&"C6",0) -> АО "НПО "Стример" | F38: Договор
C39: (наименование организации) | G39: (Реквизиты договора на поставку)
A40: 2. Подготовка продукции к контролю по НТД: | F40: выполнена
F41: (выполнена/не выполнена)
A42: 3. При входном контроле проведены следующие контрольные мероприятия:
A43: Количество, масс, объем проверенной продукции (в ед. изм.) | E43: Вид контроля (НТД) и дата сдачи образцов (проб) на контроль | F43: Приборы контроля | G43: № прибора и дата проверки прибора | H43: № и дата протокола контроля | I43: Заключение по контролю (годен/не годен)
A44: Визуальным осмотром | C44: Инструментальными и приборными методами
...

Sheet АВК 7
H1: Приложение 2
H2: к Положению
A4: ФОРМА | K4: =MID(CELL("имяфайла",A1),SEARCH("]",CELL("имяфайла",A1))+1,LEN(CELL("имяфайла",A1))) -> АВК 7
F5: соответствует | K5: =RIGHT(K4,LEN(K4)-4)+2 -> 9
F7: (результат контроля продукции)
A8: Объект строительства: | D8: ='Жвх.к (т)'!C17 -> Реконструкция ВЛ 10 кВ ДТ-9 от опоры №20 до опоры №115 в части замены опор и провода (протяженностью 8 км), с установкой коммутационных аппаратов в количестве 1 шт.
A9: Заказчик строительства: | D9: ПАО "Россети Ленэнерго"
A11: =CONCATENATE("АКТ № ",INDIRECT("'Форма журнала'!R"&K5&"C2",0)) -> АКТ № 4
A12: ВХОДНОГО КОНТРОЛЯ
G13: =INDIRECT("'Форма журнала'!R"&K5&"C3",0) -> 45607
A14: (место проведения)
A15: Нами, комиссией | C15: ='Жвх.к (т)'!B7 -> ООО «СЭТ» | F15: по Приказу №23/10/24-8 от 23.10.2024г. в составе:
C16: (организация, от которой сформирована комиссия)
A17: Председателя
A18: =CONCATENATE(ПОДПИСИ!B7," ",ПОДПИСИ!C7) -> Директор по строительству ООО «СЭТ» Потоцкий А.А.
A19: и членов комиссии:
B20: =CONCATENATE(ПОДПИСИ!B9," ",ПОДПИСИ!C9) -> Начальник участка ООО «СЭТ» Нугуманов М.А.
B21: (должность, организация, фамилия, имя, отчество)
B22: =CONCATENATE(ПОДПИСИ!B11," ",ПОДПИСИ!C11) -> Ведущий инженер строительного контроля ООО «СЭТ» Кольцов А.Г.
B23: (должность, организация, фамилия, имя, отчество)
B25: (должность, организация, фамилия, имя, отчество)
A26: руководствуясь
A27: Приказом ПАО «Россети Ленэнерго» от 20.01.2020 г. №16 «Положение по организации и осуществлению входного контроля продукции для строительства и реконструкции объектов электросетевого комплекса ПAO «Ленэнерго»
A28: (документ, устанавливающий требования по организации и проведению входного контроля продукции)
A29: составлен настоящий акт о выполненном входном контроле продукции для строительства.
A30: 1. К входному контролю представлена следующая продукция:
A31: =INDIRECT("'Форма журнала'!R"&K5&"C4",0) -> Провод линии СИП-3 1х120
A32: (наименование продукции)
A33: 1.1 Наименование, номер документа, удостоверяющего качества и НТД на продукцию:
A34: =INDIRECT("'Форма журнала'!R"&K5&"C7",0) -> Паспорт качества №№24Т1-5845 от 21.07.2024 г.; Паспорт качества №№24Т1-5844 от 21.07.2024 г.; Паспорт качества №№24Т1-5847 от 21.07.2024 г; Паспорт качества №№24Т1-5851 от 21.07.2024 г. | F34: НТД
A35: (Изготовитель, № документа и дата, № партии, Дата изготовления) | G35: (ГОСТ, ТУ, чертеж КМД)
A36: . | C36: =INDIRECT("'Форма журнала'!R"&K5&"C5",0) -> 18387 м | F36: Кол-во в партии
C37: (штуки, объем, вес в ед. изм.) | G37: (штуки, объем, вес в ед. изм)
A38: 1.3 Поставщик: | C38: =INDIRECT("'Форма журнала'!R"&K5&"C6",0) -> ООО "КЗ "ЦВЕТЛИТ" | F38: Договор
C39: (наименование организации) | G39: (Реквизиты договора на поставку)
A40: 2. Подготовка продукции к контролю по НТД: | F40: выполнена
F41: (выполнена/не выполнена)
A42: 3. При входном контроле проведены следующие контрольные мероприятия:
A43: Количество, масс, объем проверенной продукции (в ед. изм.) | E43: Вид контроля (НТД) и дата сдачи образцов (проб) на контроль | F43: Приборы контроля | G43: № прибора и дата проверки прибора | H43: № и дата протокола контроля | I43: Заключение по контролю (годен/не годен)
A44: Визуальным осмотром | C44: Инструментальными и приборными методами
...

Sheet АВК 8
H1: Приложение 2
H2: к Положению
A4: ФОРМА | K4: =MID(CELL("имяфайла",A1),SEARCH("]",CELL("имяфайла",A1))+1,LEN(CELL("имяфайла",A1))) -> АВК 8
F5: соответствует | K5: =RIGHT(K4,LEN(K4)-4)+2 -> 10
F7: (результат контроля продукции)
A8: Объект строительства: | D8: ='Жвх.к (т)'!C17 -> Реконструкция ВЛ 10 кВ ДТ-9 от опоры №20 до опоры №115 в части замены опор и провода (протяженностью 8 км), с установкой коммутационных аппаратов в количестве 1 шт.
A9: Заказчик строительства: | D9: ПАО "Россети Ленэнерго"
A11: =CONCATENATE("АКТ № ",INDIRECT("'Форма журнала'!R"&K5&"C2",0)) -> АКТ № 5
A12: ВХОДНОГО КОНТРОЛЯ
G13: =INDIRECT("'Форма журнала'!R"&K5&"C3",0) -> 45607
A14: (место проведения)
A15: Нами, комиссией | C15: ='Жвх.к (т)'!B7 -> ООО «СЭТ» | F15: по Приказу №23/10/24-8 от 23.10.2024г. в составе:
C16: (организация, от которой сформирована комиссия)
A17: Председателя
A18: =CONCATENATE(ПОДПИСИ!B7," ",ПОДПИСИ!C7) -> Директор по строительству ООО «СЭТ» Потоцкий А.А.
A19: и членов комиссии:
B20: =CONCATENATE(ПОДПИСИ!B9," ",ПОДПИСИ!C9) -> Начальник участка ООО «СЭТ» Нугуманов М.А.
B21: (должность, организация, фамилия, имя, отчество)
B22: =CONCATENATE(ПОДПИСИ!B11," ",ПОДПИСИ!C11) -> Ведущий инженер строительного контроля ООО «СЭТ» Кольцов А.Г.
B23: (должность, организация, фамилия, имя, отчество)
B25: (должность, организация, фамилия, имя, отчество)
A26: руководствуясь
A27: Приказом ПАО «Россети Ленэнерго» от 20.01.2020 г. №16 «Положение по организации и осуществлению входного контроля продукции для строительства и реконструкции объектов электросетевого комплекса ПAO «Ленэнерго»
A28: (документ, устанавливающий требования по организации и проведению входного контроля продукции)
A29: составлен настоящий акт о выполненном входном контроле продукции для строительства.
A30: 1. К входному контролю представлена следующая продукция:
A31: =INDIRECT("'Форма журнала'!R"&K5&"C4",0) -> Стойка железобетонная СВ110-3,5 (у)
A32: (наименование продукции)
A33: 1.1 Наименование, номер документа, удостоверяющего качества и НТД на продукцию:
A34: =INDIRECT("'Форма журнала'!R"&K5&"C7",0) -> Сертификат соответствия №РОСС BY.HB61.H30298 от 09.11.2021 сроком действия до 08.11.2024 | F34: НТД
A35: (Изготовитель, № документа и дата, № партии, Дата изготовления) | G35: (ГОСТ, ТУ, чертеж КМД)
A36: . | C36: =INDIRECT("'Форма журнала'!R"&K5&"C5",0) -> 6 шт. | F36: Кол-во в партии
C37: (штуки, объем, вес в ед. изм.) | G37: (штуки, объем, вес в ед. изм)
A38: 1.3 Поставщик: | C38: =INDIRECT("'Форма журнала'!R"&K5&"C6",0) -> ЗАО "Митеп-Волга" | F38: Договор
C39: (наименование организации) | G39: (Реквизиты договора на поставку)
A40: 2. Подготовка продукции к контролю по НТД: | F40: выполнена
F41: (выполнена/не выполнена)
A42: 3. При входном контроле проведены следующие контрольные мероприятия:
A43: Количество, масс, объем проверенной продукции (в ед. изм.) | E43: Вид контроля (НТД) и дата сдачи образцов (проб) на контроль | F43: Приборы контроля | G43: № прибора и дата проверки прибора | H43: № и дата протокола контроля | I43: Заключение по контролю (годен/не годен)
A44: Визуальным осмотром | C44: Инструментальными и приборными методами
...

Sheet АВК 10
H1: Приложение 2
H2: к Положению
A4: ФОРМА | K4: =MID(CELL("имяфайла",A1),SEARCH("]",CELL("имяфайла",A1))+1,LEN(CELL("имяфайла",A1))) -> АВК 10
F5: соответствует | K5: =RIGHT(K4,LEN(K4)-4)+2 -> 12
F7: (результат контроля продукции)
A8: Объект строительства: | D8: ='Жвх.к (т)'!C17 -> Реконструкция ВЛ 10 кВ ДТ-9 от опоры №20 до опоры №115 в части замены опор и провода (протяженностью 8 км), с установкой коммутационных аппаратов в количестве 1 шт.
A9: Заказчик строительства: | D9: ПАО "Россети Ленэнерго"
A11: =CONCATENATE("АКТ № ",INDIRECT("'Форма журнала'!R"&K5&"C2",0)) -> АКТ № 6
A12: ВХОДНОГО КОНТРОЛЯ
G13: =INDIRECT("'Форма журнала'!R"&K5&"C3",0) -> 45607
A14: (место проведения)
A15: Нами, комиссией | C15: ='Жвх.к (т)'!B7 -> ООО «СЭТ» | F15: по Приказу №23/10/24-8 от 23.10.2024г. в составе:
C16: (организация, от которой сформирована комиссия)
A17: Председателя
A18: =CONCATENATE(ПОДПИСИ!B7," ",ПОДПИСИ!C7) -> Директор по строительству ООО «СЭТ» Потоцкий А.А.
A19: и членов комиссии:
B20: =CONCATENATE(ПОДПИСИ!B9," ",ПОДПИСИ!C9) -> Начальник участка ООО «СЭТ» Нугуманов М.А.
B21: (должность, организация, фамилия, имя, отчество)
B22: =CONCATENATE(ПОДПИСИ!B11," ",ПОДПИСИ!C11) -> Ведущий инженер строительного контроля ООО «СЭТ» Кольцов А.Г.
B23: (должность, организация, фамилия, имя, отчество)
B25: (должность, организация, фамилия, имя, отчество)
A26: руководствуясь
A27: Приказом ПАО «Россети Ленэнерго» от 20.01.2020 г. №16 «Положение по организации и осуществлению входного контроля продукции для строительства и реконструкции объектов электросетевого комплекса ПAO «Ленэнерго»
A28: (документ, устанавливающий требования по организации и проведению входного контроля продукции)
A29: составлен настоящий акт о выполненном входном контроле продукции для строительства.
A30: 1. К входному контролю представлена следующая продукция:
A31: =INDIRECT("'Форма журнала'!R"&K5&"C4",0) -> Траверса ТМ63
A32: (наименование продукции)
A33: 1.1 Наименование, номер документа, удостоверяющего качества и НТД на продукцию:
A34: =INDIRECT("'Форма журнала'!R"&K5&"C7",0) -> Сертификат соответствия №РОСС RU.НЕ06.Н05218 от 12.04.2023 сроком действия до 11.04.2026 | F34: НТД
A35: (Изготовитель, № документа и дата, № партии, Дата изготовления) | G35: (ГОСТ, ТУ, чертеж КМД)
A36: . | C36: =INDIRECT("'Форма журнала'!R"&K5&"C5",0) -> 2 шт. | F36: Кол-во в партии
C37: (штуки, объем, вес в ед. изм.) | G37: (штуки, объем, вес в ед. изм)
A38: 1.3 Поставщик: | C38: =INDIRECT("'Форма журнала'!R"&K5&"C6",0) -> ООО "НИЛЕД" | F38: Договор
C39: (наименование организации) | G39: (Реквизиты договора на поставку)
A40: 2. Подготовка продукции к контролю по НТД: | F40: выполнена
F41: (выполнена/не выполнена)
A42: 3. При входном контроле проведены следующие контрольные мероприятия:
A43: Количество, масс, объем проверенной продукции (в ед. изм.) | E43: Вид контроля (НТД) и дата сдачи образцов (проб) на контроль | F43: Приборы контроля | G43: № прибора и дата проверки прибора | H43: № и дата протокола контроля | I43: Заключение по контролю (годен/не годен)
A44: Визуальным осмотром | C44: Инструментальными и приборными методами
...

Sheet АВК 11
H1: Приложение 2
H2: к Положению
A4: ФОРМА | K4: =MID(CELL("имяфайла",A1),SEARCH("]",CELL("имяфайла",A1))+1,LEN(CELL("имяфайла",A1))) -> АВК 11
F5: соответствует | K5: =RIGHT(K4,LEN(K4)-4)+2 -> 13
F7: (результат контроля продукции)
A8: Объект строительства: | D8: ='Жвх.к (т)'!C17 -> Реконструкция ВЛ 10 кВ ДТ-9 от опоры №20 до опоры №115 в части замены опор и провода (протяженностью 8 км), с установкой коммутационных аппаратов в количестве 1 шт.
A9: Заказчик строительства: | D9: ПАО "Россети Ленэнерго"
A11: =CONCATENATE("АКТ № ",INDIRECT("'Форма журнала'!R"&K5&"C2",0)) -> АКТ № 7
A12: ВХОДНОГО КОНТРОЛЯ
G13: =INDIRECT("'Форма журнала'!R"&K5&"C3",0) -> 45607
A14: (место проведения)
A15: Нами, комиссией | C15: ='Жвх.к (т)'!B7 -> ООО «СЭТ» | F15: по Приказу №23/10/24-8 от 23.10.2024г. в составе:
C16: (организация, от которой сформирована комиссия)
A17: Председателя
A18: =CONCATENATE(ПОДПИСИ!B7," ",ПОДПИСИ!C7) -> Директор по строительству ООО «СЭТ» Потоцкий А.А.
A19: и членов комиссии:
B20: =CONCATENATE(ПОДПИСИ!B9," ",ПОДПИСИ!C9) -> Начальник участка ООО «СЭТ» Нугуманов М.А.
B21: (должность, организация, фамилия, имя, отчество)
B22: =CONCATENATE(ПОДПИСИ!B11," ",ПОДПИСИ!C11) -> Ведущий инженер строительного контроля ООО «СЭТ» Кольцов А.Г.
B23: (должность, организация, фамилия, имя, отчество)
B25: (должность, организация, фамилия, имя, отчество)
A26: руководствуясь
A27: Приказом ПАО «Россети Ленэнерго» от 20.01.2020 г. №16 «Положение по организации и осуществлению входного контроля продукции для строительства и реконструкции объектов электросетевого комплекса ПAO «Ленэнерго»
A28: (документ, устанавливающий требования по организации и проведению входного контроля продукции)
A29: составлен настоящий акт о выполненном входном контроле продукции для строительства.
A30: 1. К входному контролю представлена следующая продукция:
A31: =INDIRECT("'Форма журнала'!R"&K5&"C4",0) -> Траверса ТМ65
A32: (наименование продукции)
A33: 1.1 Наименование, номер документа, удостоверяющего качества и НТД на продукцию:
A34: =INDIRECT("'Форма журнала'!R"&K5&"C7",0) -> Сертификат соответствия №РОСС RU.НЕ06.Н05218 от 12.04.2023 сроком действия до 11.04.2026 | F34: НТД
A35: (Изготовитель, № документа и дата, № партии, Дата изготовления) | G35: (ГОСТ, ТУ, чертеж КМД)
A36: . | C36: =INDIRECT("'Форма журнала'!R"&K5&"C5",0) -> 6 шт. | F36: Кол-во в партии
C37: (штуки, объем, вес в ед. изм.) | G37: (штуки, объем, вес в ед. изм)
A38: 1.3 Поставщик: | C38: =INDIRECT("'Форма журнала'!R"&K5&"C6",0) -> ООО "НИЛЕД" | F38: Договор
C39: (наименование организации) | G39: (Реквизиты договора на поставку)
A40: 2. Подготовка продукции к контролю по НТД: | F40: выполнена
F41: (выполнена/не выполнена)
A42: 3. При входном контроле проведены следующие контрольные мероприятия:
A43: Количество, масс, объем проверенной продукции (в ед. изм.) | E43: Вид контроля (НТД) и дата сдачи образцов (проб) на контроль | F43: Приборы контроля | G43: № прибора и дата проверки прибора | H43: № и дата протокола контроля | I43: Заключение по контролю (годен/не годен)
A44: Визуальным осмотром | C44: Инструментальными и приборными методами
...

Sheet АВК 12
H1: Приложение 2
H2: к Положению
A4: ФОРМА | K4: =MID(CELL("имяфайла",A1),SEARCH("]",CELL("имяфайла",A1))+1,LEN(CELL("имяфайла",A1))) -> АВК 12
F5: соответствует | K5: =RIGHT(K4,LEN(K4)-4)+2 -> 14
F7: (результат контроля продукции)
A8: Объект строительства: | D8: ='Жвх.к (т)'!C17 -> Реконструкция ВЛ 10 кВ ДТ-9 от опоры №20 до опоры №115 в части замены опор и провода (протяженностью 8 км), с установкой коммутационных аппаратов в количестве 1 шт.
A9: Заказчик строительства: | D9: ПАО "Россети Ленэнерго"
A11: =CONCATENATE("АКТ № ",INDIRECT("'Форма журнала'!R"&K5&"C2",0)) -> АКТ № 8
A12: ВХОДНОГО КОНТРОЛЯ
G13: =INDIRECT("'Форма журнала'!R"&K5&"C3",0) -> 45607
A14: (место проведения)
A15: Нами, комиссией | C15: ='Жвх.к (т)'!B7 -> ООО «СЭТ» | F15: по Приказу №23/10/24-8 от 23.10.2024г. в составе:
C16: (организация, от которой сформирована комиссия)
A17: Председателя
A18: =CONCATENATE(ПОДПИСИ!B7," ",ПОДПИСИ!C7) -> Директор по строительству ООО «СЭТ» Потоцкий А.А.
A19: и членов комиссии:
B20: =CONCATENATE(ПОДПИСИ!B9," ",ПОДПИСИ!C9) -> Начальник участка ООО «СЭТ» Нугуманов М.А.
B21: (должность, организация, фамилия, имя, отчество)
B22: =CONCATENATE(ПОДПИСИ!B11," ",ПОДПИСИ!C11) -> Ведущий инженер строительного контроля ООО «СЭТ» Кольцов А.Г.
B23: (должность, организация, фамилия, имя, отчество)
B25: (должность, организация, фамилия, имя, отчество)
A26: руководствуясь
A27: Приказом ПАО «Россети Ленэнерго» от 20.01.2020 г. №16 «Положение по организации и осуществлению входного контроля продукции для строительства и реконструкции объектов электросетевого комплекса ПAO «Ленэнерго»
A28: (документ, устанавливающий требования по организации и проведению входного контроля продукции)
A29: составлен настоящий акт о выполненном входном контроле продукции для строительства.
A30: 1. К входному контролю представлена следующая продукция:
A31: =INDIRECT("'Форма журнала'!R"&K5&"C4",0) -> Траверса ТМ66
A32: (наименование продукции)
A33: 1.1 Наименование, номер документа, удостоверяющего качества и НТД на продукцию:
A34: =INDIRECT("'Форма журнала'!R"&K5&"C7",0) -> Сертификат соответствия №РОСС RU.НЕ06.Н05218 от 12.04.2023 сроком действия до 11.04.2026 | F34: НТД
A35: (Изготовитель, № документа и дата, № партии, Дата изготовления) | G35: (ГОСТ, ТУ, чертеж КМД)
A36: . | C36: =INDIRECT("'Форма журнала'!R"&K5&"C5",0) -> 5 шт. | F36: Кол-во в партии
C37: (штуки, объем, вес в ед. изм.) | G37: (штуки, объем, вес в ед. изм)
A38: 1.3 Поставщик: | C38: =INDIRECT("'Форма журнала'!R"&K5&"C6",0) -> ООО "НИЛЕД" | F38: Договор
C39: (наименование организации) | G39: (Реквизиты договора на поставку)
A40: 2. Подготовка продукции к контролю по НТД: | F40: выполнена
F41: (выполнена/не выполнена)
A42: 3. При входном контроле проведены следующие контрольные мероприятия:
A43: Количество, масс, объем проверенной продукции (в ед. изм.) | E43: Вид контроля (НТД) и дата сдачи образцов (проб) на контроль | F43: Приборы контроля | G43: № прибора и дата проверки прибора | H43: № и дата протокола контроля | I43: Заключение по контролю (годен/не годен)
A44: Визуальным осмотром | C44: Инструментальными и приборными методами
...

Sheet АВК 13
H1: Приложение 2
H2: к Положению
A4: ФОРМА | K4: =MID(CELL("имяфайла",A1),SEARCH("]",CELL("имяфайла",A1))+1,LEN(CELL("имяфайла",A1))) -> АВК 13
F5: соответствует | K5: =RIGHT(K4,LEN(K4)-4)+2 -> 15
F7: (результат контроля продукции)
A8: Объект строительства: | D8: ='Жвх.к (т)'!C17 -> Реконструкция ВЛ 10 кВ ДТ-9 от опоры №20 до опоры №115 в части замены опор и провода (протяженностью 8 км), с установкой коммутационных аппаратов в количестве 1 шт.
A9: Заказчик строительства: | D9: ПАО "Россети Ленэнерго"
A11: =CONCATENATE("АКТ № ",INDIRECT("'Форма журнала'!R"&K5&"C2",0)) -> АКТ № 9
A12: ВХОДНОГО КОНТРОЛЯ
G13: =INDIRECT("'Форма журнала'!R"&K5&"C3",0) -> 45607
A14: (место проведения)
A15: Нами, комиссией | C15: ='Жвх.к (т)'!B7 -> ООО «СЭТ» | F15: по Приказу №23/10/24-8 от 23.10.2024г. в составе:
C16: (организация, от которой сформирована комиссия)
A17: Председателя
A18: =CONCATENATE(ПОДПИСИ!B7," ",ПОДПИСИ!C7) -> Директор по строительству ООО «СЭТ» Потоцкий А.А.
A19: и членов комиссии:
B20: =CONCATENATE(ПОДПИСИ!B9," ",ПОДПИСИ!C9) -> Начальник участка ООО «СЭТ» Нугуманов М.А.
B21: (должность, организация, фамилия, имя, отчество)
B22: =CONCATENATE(ПОДПИСИ!B11," ",ПОДПИСИ!C11) -> Ведущий инженер строительного контроля ООО «СЭТ» Кольцов А.Г.
B23: (должность, организация, фамилия, имя, отчество)
B25: (должность, организация, фамилия, имя, отчество)
A26: руководствуясь
A27: Приказом ПАО «Россети Ленэнерго» от 20.01.2020 г. №16 «Положение по организации и осуществлению входного контроля продукции для строительства и реконструкции объектов электросетевого комплекса ПAO «Ленэнерго»
A28: (документ, устанавливающий требования по организации и проведению входного контроля продукции)
A29: составлен настоящий акт о выполненном входном контроле продукции для строительства.
A30: 1. К входному контролю представлена следующая продукция:
A31: =INDIRECT("'Форма журнала'!R"&K5&"C4",0) -> Траверса ТМ67
A32: (наименование продукции)
A33: 1.1 Наименование, номер документа, удостоверяющего качества и НТД на продукцию:
A34: =INDIRECT("'Форма журнала'!R"&K5&"C7",0) -> Сертификат соответствия №РОСС RU.НЕ06.Н05218 от 12.04.2023 сроком действия до 11.04.2026 | F34: НТД
A35: (Изготовитель, № документа и дата, № партии, Дата изготовления) | G35: (ГОСТ, ТУ, чертеж КМД)
A36: . | C36: =INDIRECT("'Форма журнала'!R"&K5&"C5",0) -> 1 шт. | F36: Кол-во в партии
C37: (штуки, объем, вес в ед. изм.) | G37: (штуки, объем, вес в ед. изм)
A38: 1.3 Поставщик: | C38: =INDIRECT("'Форма журнала'!R"&K5&"C6",0) -> ООО "НИЛЕД" | F38: Договор
C39: (наименование организации) | G39: (Реквизиты договора на поставку)
A40: 2. Подготовка продукции к контролю по НТД: | F40: выполнена
F41: (выполнена/не выполнена)
A42: 3. При входном контроле проведены следующие контрольные мероприятия:
A43: Количество, масс, объем проверенной продукции (в ед. изм.) | E43: Вид контроля (НТД) и дата сдачи образцов (проб) на контроль | F43: Приборы контроля | G43: № прибора и дата проверки прибора | H43: № и дата протокола контроля | I43: Заключение по контролю (годен/не годен)
